<?xml version="1.0" ?>
<robot name="kobuki_x" xmlns:xacro="http://ros.org/wiki/xacro">
    <xacro:macro name="kobuki_x">
        <link name="base_footprint"/>
        <joint name="base_joint" type="fixed">
            <origin xyz="0 0 0.035" rpy="0 0 0" />
            <parent link="base_footprint"/>
            <child link="base_link" />
        </joint>
        <link name="base_link">
            <visual>
                <origin xyz="0.0 0.0 0.0" rpy="1.57079633 0 -1.57079633"/>
                <geometry>
                    <mesh filename="package://kobuki_x_description/meshes/bases/kobuki_x.stl" scale="0.001 0.001 0.001"/>
                </geometry>
                <material name="light_black">
                    <color rgba="0.26171875 0.26171875 0.26171875 1.0"/>
                </material>
            </visual>
        </link>
        <joint name="front_caster_joint" type="fixed">
            <origin xyz="0.145 0 -0.0175" rpy="0 0 0"/>
            <parent link="base_link"/>
            <child link="front_caster_link"/>
        </joint>
        <link name="front_caster_link">
            <visual>
                <origin xyz="0 0 0" rpy="1.57079633 0 0"/>
                <geometry>
                    <cylinder length="0.01" radius="0.0175"/>
                </geometry>
                <material name="light_black">
                    <color rgba="0.26171875 0.26171875 0.26171875 1.0"/>
                </material>
            </visual>
        </link>
        <joint name="back_caster_joint" type="fixed">
            <origin xyz="-0.145 0 -0.0175" rpy="0 0 0"/>
            <parent link="base_link"/>
            <child link="back_caster_link"/>
        </joint>
        <link name="back_caster_link">
            <visual>
                <origin xyz="0 0 0" rpy="1.57079633 0 0"/>
                <geometry>
                    <cylinder length="0.01" radius="0.0175"/>
                </geometry>
                <material name="light_black">
                    <color rgba="0.26171875 0.26171875 0.26171875 1.0"/>
                </material>
            </visual>
        </link>
        <joint name="wheel_left_joint" type="continuous">
            <parent link="base_link"/>
            <child link="wheel_left_link"/>
            <origin xyz="0.00 ${0.23/2} 0.0250" rpy="${-M_PI/2} 0 0"/>
            <axis xyz="0 0 1"/>
        </joint>
        <link name="wheel_left_link"/>
        <joint name="wheel_right_joint" type="continuous">
            <parent link="base_link"/>
            <child link="wheel_right_link"/>
            <origin xyz="0.00 -${0.23/2} 0.0250" rpy="${-M_PI/2} 0 0"/>
            <axis xyz="0 0 1"/>
        </joint>
        <link name="wheel_right_link"/>
    </xacro:macro>
</robot>